<?xml version="1.0" ?>
<!-- =================================================================================== -->
<!-- |    This document was autogenerated by xacro from /home/wei/Documents/RosStudy/TestRos/src/model_source/urdf/xacro/robot_model.urdf.xacro | -->
<!-- |    EDITING THIS FILE BY HAND IS NOT RECOMMENDED                                 | -->
<!-- =================================================================================== -->
<!--<robot name="my_robot" xmlns:xacro="http://wiki.ros.org/xacro">-->
<robot name="mycar">
    <link name="base_link">
        <visual>
            <geometry>
                <mesh filename="package://model_source/urdf/model/1.STL" />
            </geometry>
            <origin rpy="0 0 0" xyz="0 0 0" />
            <material name="red">
                <color rgba="1 1 1 1" />
            </material>
        </visual>
        <collision>
            <origin rpy="0 0 0" xyx="0 0 0" />
            <geometry>
                <mesh filename="package://model_source/urdf/model/1.STL" />
            </geometry>
        </collision>
        <inertial>
            <mass value="0.1" />
            <origin xyz="0 0 0" rpy="0 0 0" />
            <inertia ixx="0.03" iyy="0.03" izz="0.03" ixy="0.0" ixz="0.0" iyz="0.0" />
        </inertial>
    </link>
    <link name="link_1">
        <visual>
            <geometry>
                <mesh filename="package://model_source/urdf/model/2.STL" />
            </geometry>
            <origin rpy="0 0 0" xyz="0 0 0" />
            <material name="red">
                <color rgba="1 1 1 1" />
            </material>
        </visual>
        <collision>
            <origin rpy="0 0 0" xyx="0 0 0" />
            <geometry>
                <mesh filename="package://model_source/urdf/model/2.STL" />
            </geometry>
        </collision>
        <inertial>
            <mass value="0.1" />
            <origin xyz="0 0 0" rpy="0 0 0" />
            <inertia ixx="0.03" iyy="0.03" izz="0.03" ixy="0.0" ixz="0.0" iyz="0.0" />
        </inertial>
    </link>
    <joint name="BaseToLink_1" type="continuous">
        <parent link="base_link" />
        <child link="link_1" />
        <origin rpy="-1.5707963 0 0" xyz="0 0 0.375" />
        <axis xyz="0 1 0" />
        <limit effort="300" lower="-2.96" upper="2.96" velocity="1" />
        <dynamics damping="50" friction="1" />
    </joint>
    <link name="link_2">
        <visual>
            <geometry>
                <mesh filename="packRobotage://model_source/urdf/model/3.STL" />
            </geometry>
            <origin rpy="0 0 0" xyz="0 0 0" />
            <material name="red">
                <color rgba="1 1 1 1" />
            </material>
        </visual>
        <collision>
            <origin rpy="0 0 0" xyx="0 0 0" />
            <geometry>
                <mesh filename="package://model_source/urdf/model/3.STL" />
            </geometry>
        </collision>
        <inertial>
            <mass value="0.1" />
            <origin xyz="0 0 0" rpy="0 0 0" />
            <inertia ixx="0.03" iyy="0.03" izz="0.03" ixy="0.0" ixz="0.0" iyz="0.0" />
        </inertial>
    </link>
    <joint name="Link_1ToLink_2" type="continuous">
        <parent link="link_1" />
        <child link="link_2" />
        <origin rpy="0 0 0" xyz="0.0 0.0 0.0" />
        <axis xyz="0 0 1" />
        <limit effort="300" lower="-2.96" upper="2.96" velocity="1" />
        <dynamics damping="50" friction="1" />
    </joint>
    <link name="link_3">
        <visual>
            <geometry>
                <mesh filename="package://model_source/urdf/model/4.STL" />
            </geometry>
            <origin rpy="0 0 0" xyz="0 0 0" />
            <material name="red">
                <color rgba="1 1 1 1" />
            </material>
        </visual>
        <collision>
            <origin rpy="0 0 0" xyx="0 0 0" />
            <geometry>
                <mesh filename="package://model_source/urdf/model/4.STL" />
            </geometry>
        </collision>
        <inertial>
            <mass value="0.1" />
            <origin xyz="0 0 0" rpy="0 0 0" />
            <inertia ixx="0.03" iyy="0.03" izz="0.03" ixy="0.0" ixz="0.0" iyz="0.0" />
        </inertial>
    </link>
    <joint name="Link_2ToLink_3" type="continuous">
        <parent link="link_2" />
        <child link="link_3" />
        <origin rpy="0 0 0" xyz="0 -0.4 0.02" />
        <axis xyz="0 0 1" />
        <limit effort="300" lower="-2.96" upper="2.96" velocity="1" />
        <dynamics damping="50" friction="1" />
    </joint>
    <link name="link_4">
        <visual>
            <geometry>
                <mesh filename="package://model_source/urdf/model/5.STL" />
            </geometry>
            <origin rpy="0 0 0" xyz="0 0 0" />
            <material name="red">
                <color rgba="1 1 1 1" />
            </material>
        </visual>
        <collision>
            <origin rpy="0 0 0" xyx="0 0 0" />
            <geometry>
                <mesh filename="package://model_source/urdf/model/5.STL" />
            </geometry>
        </collision>
        <inertial>
            <mass value="0.1" />
            <origin xyz="0 0 0" rpy="0 0 0" />
            <inertia ixx="0.03" iyy="0.03" izz="0.03" ixy="0.0" ixz="0.0" iyz="0.0" />
        </inertial>
    </link>
    <joint name="Link_3ToLink_4" type="continuous">
        <parent link="link_3" />
        <child link="link_4" />
        <origin rpy="1.5707963 0 0" xyz="0 0 0" />
        <axis xyz="0 0 1" />
    </joint>
    <link name="link_5">
        <visual>
            <geometry>
                <mesh filename="package://model_source/urdf/model/6.STL" />
            </geometry>
            <origin rpy="0 0 0" xyz="0 0 0" />
            <material name="red">
                <color rgba="1 1 1 1" />
            </material>
        </visual>
        <collision>
            <origin rpy="0 0 0" xyx="0 0 0" />
            <geometry>
                <mesh filename="package://model_source/urdf/model/6.STL" />
            </geometry>
        </collision>
        <inertial>
            <mass value="0.1" />
            <origin xyz="0 0 0" rpy="0 0 0" />
            <inertia ixx="0.03" iyy="0.03" izz="0.03" ixy="0.0" ixz="0.0" iyz="0.0" />
        </inertial>
    </link>
    <joint name="Link_4ToLink_5" type="continuous">
        <parent link="link_4" />
        <child link="link_5" />
        <origin rpy="-1.5707963 0 0" xyz="0 0 0.45" />
        <axis xyz="0 0 1" />
        <limit effort="300" lower="-2.96" upper="2.96" velocity="1" />
        <dynamics damping="50" friction="1" />
    </joint>
    <link name="link_6">
        <visual>
            <geometry>
                <mesh filename="package://model_source/urdf/model/7.STL" />
            </geometry>
            <origin rpy="0 0 0" xyz="0 0 0" />
            <material name="red">
                <color rgba="1 1 1 1" />
            </material>
        </visual>
        <collision>
            <origin rpy="0 0 0" xyx="0 0 0" />
            <geometry>
                <mesh filename="package://model_source/urdf/model/7.STL" />
            </geometry>
        </collision>
        <inertial>
            <mass value="0.1" />
            <origin xyz="0 0 0" rpy="0 0 0" />
            <inertia ixx="0.03" iyy="0.03" izz="0.03" ixy="0.0" ixz="0.0" iyz="0.0" />
        </inertial>
    </link>
    <joint name="Link_5ToLink_6" type="continuous">
        <parent link="link_5" />
        <child link="link_6" />
        <origin rpy="1.5707963 0 0" xyz="0 -0.07 0" />
        <axis xyz="0 0 1" />
        <limit effort="300" lower="-2.96" upper="2.96" velocity="1" />
        <dynamics damping="50" friction="1" />
    </joint>
    <transmission name="trans_BaseToLink_1">
        <type>transmission_interface/SimpleTransmission</type>
        <joint name="BaseToLink_1">
            <hardwareInterface>hardware_interface/EffortJointInterface</hardwareInterface>
        </joint>
        <actuator name="BaseToLink_1_motor">
            <hardwareInterface>hardware_interface/EffortJointInterface</hardwareInterface>
            <mechanicalReduction>1</mechanicalReduction>
        </actuator>
    </transmission>
    <transmission name="trans_Link_1ToLink_2">
        <type>transmission_interface/SimpleTransmission</type>
        <joint name="Link_1ToLink_2">
            <hardwareInterface>hardware_interface/EffortJointInterface</hardwareInterface>
        </joint>
        <actuator name="Link_1ToLink_2_motor">
            <hardwareInterface>hardware_interface/EffortJointInterface</hardwareInterface>
            <mechanicalReduction>1</mechanicalReduction>
        </actuator>
    </transmission>
    <transmission name="trans_Link_2ToLink_3">
        <type>transmission_interface/SimpleTransmission</type>
        <joint name="Link_2ToLink_3">
            <hardwareInterface>hardware_interface/EffortJointInterface</hardwareInterface>
        </joint>
        <actuator name="Link_2ToLink_3_motor">
            <hardwareInterface>hardware_interface/EffortJointInterface</hardwareInterface>
            <mechanicalReduction>1</mechanicalReduction>
        </actuator>
    </transmission>
    <transmission name="trans_Link_3ToLink_4">
        <type>transmission_interface/SimpleTransmission</type>
        <joint name="Link_3ToLink_4">
            <hardwareInterface>hardware_interface/EffortJointInterface</hardwareInterface>
        </joint>
        <actuator name="Link_3ToLink_4_motor">
            <hardwareInterface>hardware_interface/EffortJointInterface</hardwareInterface>
            <mechanicalReduction>1</mechanicalReduction>
        </actuator>
    </transmission>
    <transmission name="trans_Link_4ToLink_5">
        <type>transmission_interface/SimpleTransmission</type>
        <joint name="Link_4ToLink_5">
            <hardwareInterface>hardware_interface/EffortJointInterface</hardwareInterface>
        </joint>
        <actuator name="Link_4ToLink_5_motor">
            <hardwareInterface>hardware_interface/EffortJointInterface</hardwareInterface>
            <mechanicalReduction>1</mechanicalReduction>
        </actuator>
    </transmission>
    <transmission name="trans_Link_5ToLink_6">
        <type>transmission_interface/SimpleTransmission</type>
        <joint name="Link_5ToLink_6">
            <hardwareInterface>hardware_interface/EffortJointInterface</hardwareInterface>
        </joint>
        <actuator name="Link_5ToLink_6_motor">
            <hardwareInterface>hardware_interface/EffortJointInterface</hardwareInterface>
            <mechanicalReduction>1</mechanicalReduction>
        </actuator>
    </transmission>
    <gazebo>
        <plugin name="gazebo_ros_control">
            <robotNamespace>/</robotNamespace>
        </plugin>
    </gazebo>
</robot>

