<robot name="mymodel">
    <link name="base_link">
        <visual>
            <geometry>
                <mesh filename="package://TestInput/urdf/model/TX2-40-HB-base_link.STL"/>
                <!--                <box size="0.5 0.2 0.1" />-->
            </geometry>
            <origin rpy="0 0 0" xyz="0 0 0"/>
            <material name="red">
                <color rgba="1 1 1 1" />
            </material>
        </visual>
    </link>
    <link name="link_1">
        <visual>
            <geometry>
                <mesh filename="package://TestInput/urdf/model/TX2-40-HB-SHOULDER.STL"/>
            </geometry>
            <origin rpy="0 0 0" xyz="0 0 0"/>
            <material name="red">
                <color rgba="1 1 1 1" />
            </material>
        </visual>
    </link>
    <joint name="baseTolink1" type="continuous">
        <parent link="base_link"/>
        <child link="link_1"/>
        <origin xyz="0 0 0" rpy="0 0 0"/>
        <axis xyz="0 0 1"/>
    </joint>

    <link name="link_2">
        <visual>
            <geometry>
                <mesh filename="package://TestInput/urdf/model/TX2-40-HB-ARM.STL"/>
            </geometry>
            <origin xyz="0 0 0" rpy="0 0 0"/>
            <material name="red">
                <color rgba="1 1 1 1"/>
            </material>
        </visual>
    </link>
    <joint name="link1Tolink2" type="continuous">
        <parent link="link_1"/>
        <child link="link_2"/>
        <origin xyz="0.0 0.0 0.0" rpy="0 0 0"/>
        <axis xyz="0 0 1"/>
    </joint>

    <link name="link_3">
        <visual>
            <geometry>
                <mesh filename="package://TestInput/urdf/model/TX2-40-HB-ELBOW.STL"/>
            </geometry>
            <origin xyz="0 0 0" rpy="0 0 0"/>
            <material name="red">
                <color rgba="1 1 1 1"/>
            </material>
        </visual>
    </link>
    <joint name="link_2Tolink_3" type="continuous">
        <parent link="link_2"/>
        <child link="link_3"/>
        <origin xyz="0 0.0 0" rpy="0 0 0"/>
        <axis xyz="0 0 1"/>
    </joint>

    <link name="link_4">
        <visual>
            <geometry>
                <mesh filename="package://TestInput/urdf/model/TX2-40-HB-FOREARM.STL"/>
            </geometry>
            <origin xyz="0 0 0" rpy="0 0 0"/>
            <material name="red">
                <color rgba="1 1 1 1"/>
            </material>
        </visual>
    </link>
    <joint name="link_3Tolink_4" type="continuous">
        <parent link="link_3"/>
        <child link="link_4"/>
        <origin xyz="0 0 0" rpy="0 0 0"/>
        <axis xyz="0 0 1"/>
    </joint>

    <link name="link_5">
        <visual>
            <geometry>
                <mesh filename="package://TestInput/urdf/model/TX2-40-HB-WRIST.STL"/>
            </geometry>
            <origin xyz="0 0 0" rpy="0 0 0"/>
            <material name="red">
                <color rgba="1 1 1 1"/>
            </material>
        </visual>
    </link>
    <joint name="link_4Tolink_5" type="continuous">
        <parent link="link_4"/>
        <child link="link_5"/>
        <origin xyz="0 0 0" rpy="0 0 0"/>
        <axis xyz="0 0 1"/>
    </joint>
</robot>